<?xml version="1.0"?>
<robot name="asb" xmlns:xacro="http://www.ros.org/wiki/xacro">
    <link name="world"/>

    <joint name="fixed" type="fixed">
        <parent link="world"/>
        <child link="body"/>
    </joint>

    <link name="body">
        <!--
            <collision>
            <origin xyz="0 0 0" rpy="0 0 0"/>
            <geometry>
                <box size="${width} ${width} ${height1}"/>
            </geometry>
            </collision>
            -->

            <visual>
                    <origin xyz="0 0 0" rpy="0 0 0"/>
                    <geometry>
                        <mesh filename="file:///home/adil/sim_ws/src/gazebo_sim/meshes/body.dae" scale="1.0 1.0 1.0" use_embedded_material="false"/>
                        <material name="red">
                            <color rgba="${255/255} ${108/255} ${10/255} 1.0"/>
                        </material>
                        <ambient>
                            <color sid="ambient">0.1 0.1 0.1 1</color>
                        </ambient>
                    </geometry>
            </visual>
            <!--
            <inertial>
            <origin xyz="0 0 1" rpy="0 0 0"/>
            <mass value="5"/>
            <inertia>
                ixx="1.0" ixy="0.0" ixz="0.0"
                iyy="1.0" iyz="0.0"
                izz="1.0"/>
            </inertial>
            -->
    </link>  
    
    <link
    name="wheel2_Link">
    <inertial>
      <origin
        xyz="0 0 0"
        rpy="0 0 0" />
      <mass
        value="0.15" />
      <inertia
        ixx="0.0002757"
        ixy="1.808E-11"
        ixz="6.9922E-11"
        iyy="0.00053956"
        iyz="6.1767E-12"
        izz="0.0002757" />
    </inertial>
    <visual>
      <origin
        xyz="0 0 0"
        rpy="0 0 0" />
      <geometry>
        <mesh
          filename="file:///home/adil/sim_ws/src/gazebo_sim/meshes/wheel2_Link.STL" />
      </geometry>
      <material
        name="abs">
        <color
          rgba="1 1 1 1" />
      </material>
    </visual>
    <collision>
      <origin
        xyz="0 0 0"
        rpy="0 0 0" />
      <geometry>
        <mesh
          filename="package://body ass/meshes/wheel2_Link.STL" />
      </geometry>
    </collision>
  </link>
  <joint
    name="wheel2"
    type="continuous">
    <origin
      xyz="0.090582 -0.19964 0.24135"
      rpy="1.5708 0 0.02049" />
    <parent
      link="base_link" />
    <child
      link="wheel2_Link" />
    <axis
      xyz="0 1 0" />
    <dynamics
      friction="0.0005" />
  </joint>






  
</robot>
