<?xml version="1.0" encoding="utf-8"?>
<!-- This URDF was automatically created by SolidWorks to URDF Exporter! Originally created by Stephen Brawner (brawner@gmail.com) 
     Commit Version: 1.5.1-0-g916b5db  Build Version: 1.5.7152.31018
     For more information, please see http://wiki.ros.org/sw_urdf_exporter -->
<robot
  name="body ass">
  <!-- .............................................................................................. -->
  <link
    name="base_link">
    <inertial>
      <origin
        xyz="0 0.150 0.150"
        rpy="1.5708 1.5708 0" />
      <mass
        value="2" />
      <inertia
        ixx="0.0011147"
        ixy="2.6411E-09"
        ixz="1.5817E-07"
        iyy="0.0013934"
        iyz="-3.9715E-08"
        izz="0.00098224" />
    </inertial>
    <visual>
      <origin
        xyz="0 0.150 0.150"
        rpy="1.5708 1.5708 0" />
      <geometry>
        <mesh
          filename="file:///home/adil/sim_ws/src/gazebo_sim/meshes/base_link.STL" />
      </geometry>
      
    </visual>
  </link>
<!-- .............................................................................................. -->
  
  <link
    name="wheel1_Link">
    <inertial>
      <origin
        xyz="0 0 0"
        rpy="0 0 0" />
      <mass
        value="0.15" />
      <inertia
        ixx="0.0002757"
        ixy="1.808E-11"
        ixz="6.9922E-11"
        iyy="0.00053956"
        iyz="6.1767E-12"
        izz="0.0002757" />
    </inertial>
    <visual>
      <origin
        xyz="0 0 0"
        rpy="0 0 0" />
      <geometry>
        <mesh
          filename="file:///home/adil/sim_ws/src/gazebo_sim/meshes/wheel1_Link.STL" />
      </geometry>
      
    </visual>
  </link>
  <!-- .............................................................................................. -->
  
  <joint
    name="wheel1"
    type="continuous">
    <origin
      xyz="0.090582 -0.19964 0.037348"
      rpy="1.5708 0 -1.0156" />
    <parent
      link="base_link" />
    <child
      link="wheel1_Link" />
    <axis
      xyz="0 1 0" />
    <dynamics
      friction="0.0005" />
  </joint>
  
  <!-- .............................................................................................. -->
</robot>

-0.00016542 0.00012827 -0.0020908

-1.7774E-08 4.4479E-08 2.1175E-08

<transmission name="wheel2">
      <type>transmission_interface/SimpleTransmission</type>
      <joint name="wheel2">
        <hardwareInterface>hardware_interface/EffortJointInterface</hardwareInterface>
      </joint>
      <actuator name="motor_wheel2">
        <hardwareInterface>hardware_interface/EffortJointInterface</hardwareInterface>
        <mechanicalReduction>1</mechanicalReduction>
      </actuator>
  </transmission>
 
 <transmission name="wheel1">
      <type>transmission_interface/SimpleTransmission</type>
      <joint name="wheel1">
        <hardwareInterface>hardware_interface/EffortJointInterface</hardwareInterface>
      </joint>
      <actuator name="motor_wheel1">
        <hardwareInterface>hardware_interface/EffortJointInterface</hardwareInterface>
        <mechanicalReduction>1</mechanicalReduction>
      </actuator>
  </transmission>